[2018-05-27 09:48:33,151] [config.py] [79] [save_to_database] [error=DataError('(pymysql.err.DataError) (1406, u"Data too long for column \'vuln_name\' at row 1")',)]
